Workbook

Sheet 1. Methodology Overview
A1: Goal-Based Portfolio Planner — Methodology Overview
A2: Index of every computed component in the application. Generated 2026-10-04 from the live source code (config.py / risk.py / allocation.py / app.py) of the submitted prototype. Legend: yellow = key stated assumption, pale-green = verified engine output, pale-red = not implemented by the app (flagged per the brief).
A4: Component | B4: What is being calculated | C4: Inputs used | D4: Method / Formula | E4: Output produced | F4: How it affects the recommendation
A5: Risk appetite (willingness) | B5: How much risk the investor says and shows they are comfortable with. | C5: Stated risk label (Low/Moderate/High); 3 scenario-quiz answers (score 2/6/10 each). | D5: willingness = 0.4 × stated_score + 0.6 × mean(quiz scores) [risk.py: risk_profile()] | E5: Score 1–10 ('willingness') | F5: One of the two numbers the final risk score is the LOWER of.
A6: Risk capacity | B6: How much risk the investor's situation can actually afford, independent of how they feel. | C6: Age, dependents, money-weighted goal horizon, emergency-fund coverage %, employment type, high-EMI flag. | D6: capacity = mean(age_pts, dependents_pts, horizon_pts, emergency_pts, employment_pts); employment_pts −2 if EMI > 40% of income. [risk.py: risk_profile()] | E6: Score 1–10 ('capacity') | F6: The other number the final risk score is the LOWER of — this is what stops an over-confident but over-committed investor from getting a portfolio they can't actually sustain.
A7: Required risk | B7: What annual return the investor's stated amount/goals would actually need to hit their targets. | C7: Investable amount, sum of all goal targets, money-weighted horizon. | D7: Binary-search solve for r such that the funding formula reaches the combined target at the weighted horizon; labelled Low/Moderate/Moderate-High/High by comparing r to the Conservative/Moderate/Aggressive planning returns at that horizon. [allocation.py: build_plan() step 6, required_return()] | E7: A return % + a label | F7: Informational only — shown as a note if it exceeds the recommended profile (e.g. "consider a larger amount / later date"). It never overrides the appetite/capacity-based recommendation.
A8: Overall risk classification | B8: Converts the two scores above into the one label used everywhere else. | C8: willingness, capacity. | D8: score = min(willingness, capacity); label: score < 4.0 → Conservative, score ≥ 7.0 → Aggressive, else Moderate. [risk.py: risk_profile(), config.CONSERVATIVE_BELOW / AGGRESSIVE_FROM] | E8: Conservative / Moderate / Aggressive + numeric score | F8: Selects which row of the allocation table (Sheet 6) is used for every goal, unless the user opens the "what-if" view and overrides it manually.
A9: Expected portfolio return | B9: The average annual return a given asset mix is expected to earn. | C9: Asset weights w; expected return per asset class (Sheet 2). | D9: μp = Σ (wi × μi) [allocation.py: portfolio_stats()] | E9: Annual % (μp) | F9: Feeds the "planning return" used to size every SIP/lumpsum requirement, and the Sharpe ratio.
A10: Portfolio volatility | B10: How much a given mix's annual return typically swings around its average. | C10: Asset weights w; per-asset volatility σi; the 5×5 correlation matrix ρ (Sheet 2/4). | D10: σp = √(wᵗ · Cov · w), where Cov = outer(σ,σ) ⊙ ρ [allocation.py: portfolio_stats()] | E10: Annual % (σp) | F10: Used for the Sharpe ratio, the "bad year"/"stress decline" figures, and the Monte Carlo simulation's month-to-month noise.
A11: Sharpe ratio | B11: Return earned per unit of risk taken, versus a safe benchmark. | C11: μp, σp, risk-free rate (6.5%, config.RISK_FREE_RATE). | D11: Sharpe = (μp − rf) / σp [allocation.py: sharpe_ratio()] | E11: A ratio (e.g. 0.36) | F11: Shown behind an "advanced" expander for comparing the 3 options; not used anywhere in the funding math.
A12: Goal future value | B12: What a goal will actually cost on its target date, after inflation. | C12: Today's cost, years to go, goal-type inflation category (Sheet 2). | D12: target = cost × (1 + inflation_rate) ^ years [risk.py: build_goals()] | E12: ₹ target | F12: This is the number every SIP/lumpsum requirement is solved against — get this wrong and everything downstream is wrong, so it is the first thing computed.
A13: SIP requirement | B13: The monthly contribution needed to reach a goal's future value. | C13: Target, years, the goal's own "planning return" (from its own allocation), SIP step-up %. | D13: No step-up: SIP = target × rm ⁄ ((1+rm)^months − 1), rm = (1+g)^(1/12) − 1. With step-up: solved by binary search on the month-by-month compounding. [allocation.py: required_funding()] | E13: ₹ / month | F13: Compared against the money actually available (after the emergency-fund top-up and priority ordering) to produce each goal's "% funded" figure.
A14: Lump-sum future value / requirement | B14: The lumpsum needed today to reach a goal's future value. | C14: Target, years, planning return g. | D14: required = target ⁄ (1+g)^years, i.e. the inverse of FV = PV×(1+r)^n [allocation.py: required_funding()] | E14: ₹ (today) | F14: Same funding/funded-ratio mechanism as the SIP case, used whenever the investor chose Lumpsum mode.
A15: Inflation adjustment | B15: Different goal types are assumed to get expensive at different rates. | C15: Goal category (General / Education / Healthcare / Travel / Housing), years. | D15: Compounded at the category's own rate, not one flat number for every goal. [config.GOAL_INFLATION] | E15: An inflated ₹ target (feeds "Goal future value" above) | F15: A Healthcare or Education goal is sized noticeably higher than the same today's-cost General goal over the same horizon.
... A20: Rebalancing logic | B20: Guidance on when to review / rebalance the recommended mix over time. | C20: None — this is currently a fixed block of advisory text, not a computed rule. | D20: Methodology currently undefined — recommended rule required. The app only displays a static tip ("review at least once a year, or sooner if any asset class drifts more than about 5 percentage points from its target") in app.py; no code measures actual drift from any portfolio data or re-triggers anything automatically. | E20: Static text only (no computed output) | F20: None — does not feed back into the recommendation engine at all.

Sheet 2. Assumptions
A1: Assumptions
A2: Every stated, tunable number the engine runs on, exactly as written in config.py and data/assumptions.csv — nothing here is hidden inside a formula. Values in blue are the raw numbers used by the code today.
A4: Assumption | B4: Value | C4: Unit | D4: Reason / basis | E4: Where it is used
A5: Liquid Fund — expected return | B5: 0.06 | C5: %/yr | D5: Placeholder, directionally in line with short-term liquid-fund yields. Not fitted to downloaded data for this submission. | E5: config._DEFAULTS / data/assumptions.csv; allocation.portfolio_stats()
A6: Debt Fund — expected return | B6: 0.07 | C6: %/yr | D6: Placeholder, mid-single-digit debt-fund range. | E6: config._DEFAULTS / data/assumptions.csv
A7: Gold — expected return | B7: 0.08 | C7: %/yr | D7: Placeholder, broadly in line with cited long-run gold returns. | E7: config._DEFAULTS / data/assumptions.csv
A8: Large-cap Equity — expected return | B8: 0.12 | C8: %/yr | D8: Placeholder, roughly Nifty-50-type large-cap range. | E8: config._DEFAULTS / data/assumptions.csv
A9: Mid-cap Equity — expected return | B9: 0.14 | C9: %/yr | D9: Placeholder, roughly Nifty-Midcap-type range. | E9: config._DEFAULTS / data/assumptions.csv
A10: Indian equity — one blended figure | B10: N/A | C10: — | D10: The app does not use a single blended "Indian equity" return. It models equity as two separate asset classes (Large-cap and Mid-cap, above), each with its own return/volatility. | E10: See the two rows above
A11: International equity — expected return | B11: Not implemented | C11: — | D11: Methodology currently undefined — recommended rule required. The app has exactly 5 asset classes (config.ASSETS); there is no international-equity bucket anywhere in the code. | E11: —
A12: Risk-free rate | B12: 0.065 | C12: %/yr | D12: Placeholder — approx. short-term G-Sec / liquid-fund yield; used only for the Sharpe-ratio calculation, nowhere else. | E12: config.RISK_FREE_RATE; allocation.sharpe_ratio()
A13: Expected (general) inflation | B13: 0.06 | C13: %/yr | D13: Stated planning assumption for goals with no specific category. | E13: config.INFLATION; config.GOAL_INFLATION['General']
A14: Education inflation | B14: 0.08 | C14: %/yr | D14: Education costs are assumed to rise faster than general CPI. | E14: config.GOAL_INFLATION['Education']
A15: Healthcare inflation | B15: 0.09 | C15: %/yr | D15: Healthcare costs are assumed to rise fastest of the categories modelled. | E15: config.GOAL_INFLATION['Healthcare']
A16: Travel inflation | B16: 0.06 | C16: %/yr | D16: Same as general inflation. | E16: config.GOAL_INFLATION['Travel']
A17: Housing inflation | B17: 0.07 | C17: %/yr | D17: Assumed slightly above general inflation. | E17: config.GOAL_INFLATION['Housing']
A18: Salary growth | B18: Not implemented | C18: — | D18: Methodology currently undefined — recommended rule required. The app has no income-growth assumption at all. The SIP step-up rate (below) grows the *contribution amount* the user chooses, which is a related but different thing from the user's salary growing. | E18: —
A19: SIP annual step-up (default) | B19: 0 | C19: %/yr | D19: 0% unless the user sets a different value in the Money & goals step; used to size a growing SIP via month-by-month compounding. | E19: config.DEFAULT_SIP_STEP_UP; allocation._sip_future_value(), required_funding()
A20: Liquid Fund — volatility | B20: 0.01 | C20: %/yr (σ) | D20: Placeholder. | E20: config._DEFAULTS / data/assumptions.csv
A21: Debt Fund — volatility | B21: 0.03 | C21: %/yr (σ) | D21: Placeholder. | E21: config._DEFAULTS / data/assumptions.csv
A22: Gold — volatility | B22: 0.14 | C22: %/yr (σ) | D22: Placeholder. | E22: config._DEFAULTS / data/assumptions.csv
A23: Large-cap Equity — volatility | B23: 0.17 | C23: %/yr (σ) | D23: Placeholder. | E23: config._DEFAULTS / data/assumptions.csv
A24: Mid-cap Equity — volatility | B24: 0.22 | C24: %/yr (σ) | D24: Placeholder. | E24: config._DEFAULTS / data/assumptions.csv
A25: Asset-class correlations (ρ) | B25: see matrix below | C25: — | D25: Stated, not fitted to data — e.g. equity–debt ≈ 0.10, Large-cap–Mid-cap ≈ 0.85 (the two equity sub-classes move closely together). | E25: config.CORR / allocation.py (used to build the covariance matrix)
A26: Default retirement age | B26: 60 | C26: years | D26: Not a config.py constant — it is a UI widget default hardcoded in app.py's "Retirement age" number input (min 35). The user can change it; there is no centrally documented default the way the other assumptions are. | E26: app.py, retirement-age widget
A27: Emergency fund — base months (Salaried) | B27: 4 | C27: months | D27: Commonly cited retail planning heuristic, not a regulatory requirement. | E27: config.EMERGENCY_MONTHS_BASE
A28: Emergency fund — base months (Self-employed / business owner) | B28: 8 | C28: months | D28: Less predictable income → larger buffer. | E28: config.EMERGENCY_MONTHS_BASE
A29: Emergency fund — base months (Freelancer / professional) | B29: 8 | C29: months | D29: Same reasoning as self-employed. | E29: config.EMERGENCY_MONTHS_BASE
A30: Emergency fund — base months (Student) | B30: 3 | C30: months | D30: Lower essential-expense base case assumed. | E30: config.EMERGENCY_MONTHS_BASE
A31: Emergency fund — base months (Retired) | B31: 6 | C31: months | D31: No active income to replace. | E31: config.EMERGENCY_MONTHS_BASE
A32: Emergency fund — base months (Other) | B32: 6 | C32: months | D32: Default fallback. | E32: config.EMERGENCY_MONTHS_BASE
A33: Emergency fund — extra per dependent | B33: 1 | C33: months | D33: Each financial dependent adds one month of buffer. | E33: config.EMERGENCY_MONTHS_PER_DEPENDENT
A34: Emergency fund — cap | B34: 12 | C34: months | D34: Never ask for more than a year's buffer. | E34: config.EMERGENCY_MONTHS_CAP
A35: High EMI-burden threshold | B35: 0.4 | C35: % of income | D35: EMI above this share of income is flagged as a high debt burden and reduces risk-capacity points. | E35: config.HIGH_EMI_BURDEN_RATIO
A36: High-interest debt threshold | B36: 0.12 | C36: %/yr | D36: Loans costlier than this trigger a "repay before investing more" note (the rate itself is entered by the user as a yes/no flag, not compared numerically in code). | E36: config.HIGH_INTEREST_DEBT_RATE
A37: Existing-portfolio offset | B37: 0.5 | C37: 0–1 scale | D37: How strongly new money is tilted away from an already-concentrated existing portfolio. 0 = ignore existing holdings, 1 = fully offset them. | E37: config.EXISTING_PORTFOLIO_OFFSET; allocation.tilt_for_existing()
... A46: Monte Carlo random seed | B46: 42 | C46: — | D46: Fixed, so identical inputs always reproduce identical results — important for a demo/viva. | E46: config.SEED
A48: Asset-class correlation matrix (ρ) — config.CORR, used by allocation.portfolio_stats()
B49: Liquid Fund | C49: Debt Fund | D49: Gold | E49: Large-cap Equity | F49: Mid-cap Equity
A50: Liquid Fund | B50: 1 | C50: 0.5 | D50: 0 | E50: 0 | F50: 0
...

Sheet 3. Core Calculations
A1: Core Financial Calculations
A2: The six closed-form calculations the engine runs on every goal. Each has a live, editable worked example below the summary table — change a blue input cell and the black formula cells recompute.
A4: Calculation | B4: Formula used by the app | C4: Variables | D4: Where in the code
A5: Lump-Sum Future Value | B5: FV = PV × (1 + r) ^ n (app uses the inverse: required PV = target ÷ (1+g)^years) | C5: PV = amount invested today, r = annual return, n = years | D5: allocation.required_funding() (sip=False branch)
A6: SIP Future Value | B6: Month-by-month: v=0; for each month t (year_idx = t÷12): v += c₀×(1+step_up)^year_idx; then v ×= (1+rm), where rm = (1+g)^(1/12) − 1. (This is an annuity-DUE pattern — the month's contribution is added *before* that month's growth is applied.) | C6: c₀ = first month's SIP, g = annual planning return, step_up = annual SIP growth %, rm = the equivalent monthly rate | D6: allocation._sip_future_value()
A7: Required SIP (monthly) | B7: No step-up: SIP = target × rm ÷ ((1+rm)^months − 1). With step-up: solved by a 60-iteration binary search so that _sip_future_value(SIP, months, rm, step_up) = target. | C7: target = inflated goal value, months = years×12, rm as above | D7: allocation.required_funding()
A8: Inflation-Adjusted Goal Value | B8: Future Goal Cost = Current Cost × (1 + inflation_rate) ^ years — inflation_rate is the goal's OWN category rate (Sheet 2), not one flat number for every goal. | C8: Current Cost = today's rupee cost, inflation_rate = category rate, years = time to goal | D8: risk.build_goals()
A9: Real Return | B9: Real Return = (1 + Nominal Return) ÷ (1 + Inflation) − 1 | C9: Nominal Return = expected portfolio return, Inflation = config.INFLATION (6%) | D9: Methodology currently undefined — recommended rule required. This standard formula is not computed or shown anywhere in the current app — every return figure displayed to the user is nominal.
A10: Portfolio Expected Return | B10: Expected Portfolio Return = Σ (Asset Weight × Expected Asset Return) | C10: Weight and expected return of each of the 5 asset classes (Sheet 2) | D10: allocation.portfolio_stats()
A12: Worked example 1 — Lump-Sum Future Value (FV = PV × (1+r)^n)
A13: Amount invested today (PV) | B13: 100000 | C13: Annual return (r) | D13: 0.1
A14: Years (n) | B14: 6 | C14: Future value (FV) | D14: =B13*(1+D13)^B14 -> 177156.1
A16: Worked example 2 — SIP Future Value, month-by-month (first 12 months shown; the app repeats this same step for every month of the goal's horizon)
A17: First month's SIP (c0) | B17: 10000 | C17: Annual planning return (g) | D17: 0.0927
A18: Annual SIP step-up | B18: 0 | C18: Monthly rate rm = (1+g)^(1/12)-1 | D18: =(1+D17)^(1/12)-1 -> 0.0074149974
A19: Month | B19: Contribution this month | C19: Balance after this month's growth
A20: 1 | B20: =$B$17*(1+$B$18)^(INT((A20-1)/12)) -> 10000 | C20: =B20*(1+$D$18) -> 10074.15
A21: 2 | B21: =$B$17*(1+$B$18)^(INT((A21-1)/12)) -> 10000 | C21: =(C20+B21)*(1+$D$18) -> 20223
A22: 3 | B22: =$B$17*(1+$B$18)^(INT((A22-1)/12)) -> 10000 | C22: =(C21+B22)*(1+$D$18) -> 30447.103
A23: 4 | B23: =$B$17*(1+$B$18)^(INT((A23-1)/12)) -> 10000 | C23: =(C22+B23)*(1+$D$18) -> 40747.018
A24: 5 | B24: =$B$17*(1+$B$18)^(INT((A24-1)/12)) -> 10000 | C24: =(C23+B24)*(1+$D$18) -> 51123.307
A25: 6 | B25: =$B$17*(1+$B$18)^(INT((A25-1)/12)) -> 10000 | C25: =(C24+B25)*(1+$D$18) -> 61576.537
A26: 7 | B26: =$B$17*(1+$B$18)^(INT((A26-1)/12)) -> 10000 | C26: =(C25+B26)*(1+$D$18) -> 72107.276
A27: 8 | B27: =$B$17*(1+$B$18)^(INT((A27-1)/12)) -> 10000 | C27: =(C26+B27)*(1+$D$18) -> 82716.102
A28: 9 | B28: =$B$17*(1+$B$18)^(INT((A28-1)/12)) -> 10000 | C28: =(C27+B28)*(1+$D$18) -> 93403.591
A29: 10 | B29: =$B$17*(1+$B$18)^(INT((A29-1)/12)) -> 10000 | C29: =(C28+B29)*(1+$D$18) -> 104170.33
A30: 11 | B30: =$B$17*(1+$B$18)^(INT((A30-1)/12)) -> 10000 | C30: =(C29+B30)*(1+$D$18) -> 115016.9
A31: 12 | B31: =$B$17*(1+$B$18)^(INT((A31-1)/12)) -> 10000 | C31: =(C30+B31)*(1+$D$18) -> 125943.9
A32: Balance after 12 months is the SIP future value after 1 year, computed exactly the way allocation._sip_future_value() does it internally — the app simply continues this loop for the full number of months in the goal's horizon.
A34: Worked example 3 — Required SIP (no step-up): SIP = target × rm ÷ ((1+rm)^months − 1)
A35: Target (inflated goal value) | B35: 2127778.7 | C35: Months | D35: 72
A36: Annual planning return (g) | B36: 0.0927 | C36: Monthly rate rm | D36: =(1+B36)^(1/12)-1 -> 0.0074149974
A37: Required monthly SIP | B37: =B35*D36/((1+D36)^D35-1) -> 22469.25
A38: Note: this closed-form "ordinary annuity" formula is what required_funding() actually uses for the no-step-up case, but allocation.simulate()/_sip_future_value() compound as an "annuity-due" (contribution added, then grown, each month — see Worked example 2). Plugging this SIP back into the app's own month-by-month engine lands about 0.6-0.8% ABOVE the target rather than exactly on it, i.e. this formula is a small, documented over-estimate (asks for slightly more than strictly required), not an error — verified numerically for this project's own Marriage goal figures.
A40: Worked example 4 — Inflation-Adjusted Goal Value: Future Cost = Cost × (1+inflation)^years
A41: Today's cost | B41: 1500000 | C41: Category inflation (General) | D41: 0.06
A42: Years to goal | B42: 6
A43: Inflated target | B43: =B41*(1+D41)^B42 -> 2127778.7
A45: Worked example 5 — Real Return (NOT currently computed by the app; shown per brief)
A46: Nominal return | B46: 0.111 | C46: Inflation | D46: 0.06
...

Sheet 4. Risk Metrics
A1: Risk & Portfolio Metrics
A2: How the app measures a portfolio's risk, built from real correlations (linked from Sheet 2, shown in green) so this recalculates if an assumption changes.
A4: Portfolio volatility (standard deviation), with correlations
A5: σp² = Σ wi²σi² + 2·Σᵢ<ⱼ wi·wj·σi·σj·ρij then σp = √(portfolio variance) [allocation.portfolio_stats(), using Cov = outer(σ,σ) ⊙ ρ]
A6: wi = weight in asset i, σi = volatility of asset i, ρij = correlation between assets i and j (Sheet 2).
A8: Worked example — recommended Aggressive / Long-horizon allocation (Retirement goal, Sheet 7)
A9: Asset class | B9: Weight | C9: Volatility (σ, from Sheet 2)
A10: Liquid Fund | B10: 0 | C10: ='2. Assumptions'!B20 -> 0.01
A11: Debt Fund | B11: 0.05 | C11: ='2. Assumptions'!B21 -> 0.03
A12: Gold | B12: 0.05 | C12: ='2. Assumptions'!B22 -> 0.14
A13: Large-cap Equity | B13: 0.5 | C13: ='2. Assumptions'!B23 -> 0.17
A14: Mid-cap Equity | B14: 0.4 | C14: ='2. Assumptions'!B24 -> 0.22
A16: Covariance matrix (Covᵢⱼ = σi × σj × ρij, ρ linked from Sheet 2)
B17: Liquid Fund | C17: Debt Fund | D17: Gold | E17: Large-cap Equity | F17: Mid-cap Equity
A18: Liquid Fund | B18: =$C$10*$C$10*'2. Assumptions'!B50 -> 0.0001 | C18: =$C$10*$C$11*'2. Assumptions'!C50 -> 0.00015 | D18: =$C$10*$C$12*'2. Assumptions'!D50 -> 0 | E18: =$C$10*$C$13*'2. Assumptions'!E50 -> 0 | F18: =$C$10*$C$14*'2. Assumptions'!F50 -> 0
A19: Debt Fund | B19: =$C$11*$C$10*'2. Assumptions'!B51 -> 0.00015 | C19: =$C$11*$C$11*'2. Assumptions'!C51 -> 0.0009 | D19: =$C$11*$C$12*'2. Assumptions'!D51 -> 0.00042 | E19: =$C$11*$C$13*'2. Assumptions'!E51 -> 0.00051 | F19: =$C$11*$C$14*'2. Assumptions'!F51 -> 0.00033
A20: Gold | B20: =$C$12*$C$10*'2. Assumptions'!B52 -> 0 | C20: =$C$12*$C$11*'2. Assumptions'!C52 -> 0.00042 | D20: =$C$12*$C$12*'2. Assumptions'!D52 -> 0.0196 | E20: =$C$12*$C$13*'2. Assumptions'!E52 -> 0.00119 | F20: =$C$12*$C$14*'2. Assumptions'!F52 -> 0.00154
A21: Large-cap Equity | B21: =$C$13*$C$10*'2. Assumptions'!B53 -> 0 | C21: =$C$13*$C$11*'2. Assumptions'!C53 -> 0.00051 | D21: =$C$13*$C$12*'2. Assumptions'!D53 -> 0.00119 | E21: =$C$13*$C$13*'2. Assumptions'!E53 -> 0.0289 | F21: =$C$13*$C$14*'2. Assumptions'!F53 -> 0.03179
A22: Mid-cap Equity | B22: =$C$14*$C$10*'2. Assumptions'!B54 -> 0 | C22: =$C$14*$C$11*'2. Assumptions'!C54 -> 0.00033 | D22: =$C$14*$C$12*'2. Assumptions'!D54 -> 0.00154 | E22: =$C$14*$C$13*'2. Assumptions'!E54 -> 0.03179 | F22: =$C$14*$C$14*'2. Assumptions'!F54 -> 0.0484
A24: Portfolio variance = wᵀ · Cov · w (matrix form); Portfolio SD = √variance
A25: Portfolio variance (σp²) | B25: =MMULT(MMULT(TRANSPOSE(B10:B14),B18:F22),B10:B14) -> 0.02789815
A26: Portfolio volatility (σp) | B26: =SQRT(B25) -> 0.16702739
A28: Sharpe ratio: (Expected Portfolio Return − Risk-Free Rate) ÷ Portfolio Volatility
A29: Expected portfolio return (μp) | B29: 0.1235 | C29: Risk-free rate (Sheet 2) | D29: ='2. Assumptions'!B12 -> 0.065
A30: Portfolio volatility (σp, from above) | B30: =B26 -> 0.16702739
A31: Sharpe ratio | B31: =(B29-D29)/B30 -> 0.35024195
A33: Other metrics referenced in the brief — what the app actually computes
A34: Metric | B34: Formula / inputs | C34: Interpretation | D34: Where it appears in the app
A35: "Bad year" (a real, implemented downside estimate) | B35: μp − 1.645 × σp | C35: An analytical, roughly 1-in-20 (5th percentile) bad-year return, assuming a normal distribution — not a historical event. | D35: allocation.build_plan(), shown behind the "advanced" expander
A36: Stress decline (a real, implemented downside estimate) | B36: μp − 2.0 × σp | C36: A rarer, sharper hypothetical one-year decline than the bad-year figure — still an analytical estimate from the assumed volatility. | D36: allocation.build_plan(), "advanced" expander, with a tooltip explaining it is not a historical drawdown
A37: Maximum drawdown (peak-to-trough, historical or path-simulated) | B37: Not implemented | C37: Methodology currently undefined — recommended rule required. The app has no multi-period path output to measure a peak-to-trough decline from; "bad year" and "stress decline" above are single-year analytical substitutes, not a true max drawdown. | D37: —
A38: Goal achievement probability | B38: share of 2,000 Monte Carlo simulated futures whose ending value ≥ the goal's inflated target | C38: A real, implemented metric — directly answers "how likely am I to reach this goal at this contribution level?" | D38: allocation.simulate() → the 'prob' field; shown as "Chance of reaching your goal"
A39: Expected downside | B39: Covered by "bad year" / "stress decline" above | C39: The app does not compute a separate "expected downside"/"expected shortfall" (CVaR) figure; the two rows above are its actual downside metrics. | D39: —
A40: Real return | B40: See Sheet 3 | C40: Methodology currently undefined — recommended rule required (not computed anywhere in the app; see Sheet 3 for the textbook formula). | D40: —

Sheet 5. Risk Profiling
A1: Risk Profiling & Recommendation Logic
A2: How the app turns a user's answers into a deterministic, reproducible risk profile — no step here is ever left to the LLM to decide.
A4: RISK APPETITE ("willingness") — behavioural, from the stated label + a 3-question scenario quiz
A5: Factor | B5: Possible input | C5: Score / adjustment | D5: Reason | E5: Effect on final risk profile
A6: Stated risk appetite (40% of willingness) | B6: Low / Moderate / High | C6: 3 / 6 / 9 (risk.STATED_SCORE) | D6: A simple self-reported label, given less weight than actual behaviour. | E6: Blended into willingness below.
A7: Scenario Q1 — markets fall 20% in a month | B7: Sell everything / Do nothing / Invest more | C7: 2 / 6 / 10 | D7: Panic-selling signals low real risk tolerance; buying the dip signals high tolerance. | E7: One of 3 quiz answers averaged, then 60% of willingness.
A8: Scenario Q2 — preferred 5-year outcome | B8: Steady ~7%, no loss / ~10% with ≤15% dips / ~13% with ≤30% dips | C8: 2 / 6 / 10 | D8: Directly trades expected return against drawdown comfort. | E8: Same as above.
A9: Scenario Q3 — flexibility on the goal date | B9: Very important, cannot delay / could delay ~1yr / flexible | C9: 2 / 6 / 10 | D9: Inflexible dates need safer, more predictable money. | E9: Same as above.
A10: Willingness (combined) | B10: — | C10: willingness = 0.4 × stated_score + 0.6 × mean(Q1,Q2,Q3) | D10: Behaviour (60%) is weighted above the self-reported label (40%) because stated risk tolerance is well known to be an unreliable predictor of actual investor behaviour. | E10: One of the two inputs the final score takes the LOWER of.
A12: RISK CAPACITY — what the investor's situation can actually afford
A13: Factor | B13: Possible input | C13: Score / adjustment | D13: Reason | E13: Effect on final risk profile
A14: Age | B14: ≤30 / 31–40 / 41–50 / 51–60 / 61+ | C14: 9 / 7 / 5 / 3 / 2 | D14: Younger investors have more time to recover from a bad market. | E14: 1 of 5 factors averaged into capacity.
A15: Dependents | B15: 0 / 1 / 2 / 3+ | C15: 9 / 7 / 5 / 3 | D15: More financial dependents = less room to take investment risk. | E15: Same.
A16: Money-weighted goal horizon | B16: Any number of years (rupee-size-weighted average across all goals) | C16: horizon_pts = clamp(1, 10, 1 + 0.6 × weighted_years) | D16: Longer overall horizon supports more risk. | E16: Same.
A17: Emergency-fund coverage | B17: 0% to 100%+ of the target met | C17: emergency_pts = 2 + 7 × min(1, current ÷ target) | D17: No safety buffer = any market dip could force an untimely withdrawal. | E17: Same.
A18: Employment stability | B18: Salaried / Self-employed / Freelancer / Student / Retired / Other | C18: 7 / 5 / 4 / 5 / 3 / 5 (config.EMPLOYMENT_CAPACITY_PTS) | D18: More predictable income supports more capacity for market risk. | E18: Same, then −2 (floor 1) if EMI is a high burden (below).
A19: High EMI burden | B19: EMI > 40% of monthly income? | C19: Employment points − 2 (never below 1) | D19: A heavy debt load reduces how much risk the household can really afford, on top of the stability score. | E19: Adjusts the employment-stability factor above.
A20: Liquidity need (collected but NOT scored) | B20: Low / Some / High — collected in the UI | C20: No effect on any score today | D20: Methodology currently undefined — recommended rule required. LIMITATIONS.md already documents this: the field is collected and shown back to the user, but risk_profile()/build_plan() never read it. | E20: None currently.
A21: Capacity (combined) | B21: — | C21: capacity = mean(age_pts, dependents_pts, horizon_pts, emergency_pts, employment_pts) | D21: A simple unweighted average of the 5 factors above. | E21: The other input the final score takes the LOWER of.
A23: REQUIRED RISK — the return the stated goals would actually need (shown for awareness only; never overrides the two scores above)
A24: Factor | B24: Possible input | C24: Score / adjustment | D24: Reason | E24: Effect on final risk profile
A25: Required return | B25: Investable amount, every goal's inflated target, money-weighted horizon | C25: Binary search for r solving the funding formula at the weighted horizon | D25: The return the plan would need if nothing about the goals/amount changes. | E25: Compared to the 3 profiles' planning returns at that horizon to get a label.
A26: Required-risk label | B26: The required return above | C26: Low / Moderate / Moderate-High / High (vs. the Conservative/Moderate/Aggressive planning returns at that horizon) | D26: Translates a % into the same vocabulary as the recommended profile. | E26: Surfaced as a note (e.g. "you'd need ~13.2%/yr — higher than your recommended profile targets") - it never changes the recommended profile itself.
A28: Combining willingness + capacity into the final label
A29: score = clamp(1, 10, MIN(willingness, capacity)) — the LOWER of the two, never a blended average: standard planning practice is to never recommend more risk than a client can either stomach OR afford, whichever is more restrictive. [risk.py: risk_profile()]
A30: Score range | B30: Label actually used by the app | C30: config.py constant
A31: score < 4.0 | B31: Conservative | C31: CONSERVATIVE_BELOW = 4.0
A32: 4.0 ≤ score < 7.0 | B32: Moderate | C32: (the band between the two cutoffs)
A33: score ≥ 7.0 | B33: Aggressive | C33: AGGRESSIVE_FROM = 7.0
A35: Methodology currently undefined — recommended rule required, relative to this brief: the brief's suggested taxonomy is 5 tiers (Conservative / Moderately Conservative / Balanced / Moderately Aggressive / Aggressive). The application as built only implements 3 tiers (Conservative / Moderate / Aggressive) — shown above, exactly as coded in risk.py. Splitting each existing band in half (at score≈5.5 for "Moderately Conservative" vs "Balanced", etc.) would be a natural extension, but no such split exists in the current code, so this workbook documents the 3-tier rule the app actually runs today rather than inventing a 5th label.

Sheet 6. Portfolio Construction
A1: Portfolio Construction Logic
A2: How the final asset mix for each goal, and the overall portfolio, is actually built.
A4: Base allocation table — ALLOC[horizon bucket][risk profile] (allocation.py, the exact percentages the app uses)
A5: Horizon bucket | B5: Risk profile | C5: Liquid Fund | D5: Debt Fund | E5: Gold | F5: Large-cap Equity | G5: Mid-cap Equity | H5: Equity % | I5: Lookup key (for Sheet 7's formulas)
A6: Short (≤3 yrs) | B6: Conservative | C6: 0.7 | D6: 0.3 | E6: 0 | F6: 0 | G6: 0 | H6: =SUM(F6:G6) -> 0 | I6: =A6&"|"&B6 -> Short (≤3 yrs)|Conservative
A7: Short (≤3 yrs) | B7: Moderate | C7: 0.55 | D7: 0.35 | E7: 0.05 | F7: 0.05 | G7: 0 | H7: =SUM(F7:G7) -> 0.05 | I7: =A7&"|"&B7 -> Short (≤3 yrs)|Moderate
A8: Short (≤3 yrs) | B8: Aggressive | C8: 0.4 | D8: 0.4 | E8: 0.05 | F8: 0.15 | G8: 0 | H8: =SUM(F8:G8) -> 0.15 | I8: =A8&"|"&B8 -> Short (≤3 yrs)|Aggressive
A9: Medium (3–7 yrs) | B9: Conservative | C9: 0.1 | D9: 0.55 | E9: 0.1 | F9: 0.25 | G9: 0 | H9: =SUM(F9:G9) -> 0.25 | I9: =A9&"|"&B9 -> Medium (3–7 yrs)|Conservative
A10: Medium (3–7 yrs) | B10: Moderate | C10: 0.05 | D10: 0.35 | E10: 0.1 | F10: 0.4 | G10: 0.1 | H10: =SUM(F10:G10) -> 0.5 | I10: =A10&"|"&B10 -> Medium (3–7 yrs)|Moderate
A11: Medium (3–7 yrs) | B11: Aggressive | C11: 0 | D11: 0.2 | E11: 0.1 | F11: 0.45 | G11: 0.25 | H11: =SUM(F11:G11) -> 0.7 | I11: =A11&"|"&B11 -> Medium (3–7 yrs)|Aggressive
A12: Long (>7 yrs) | B12: Conservative | C12: 0 | D12: 0.4 | E12: 0.1 | F12: 0.4 | G12: 0.1 | H12: =SUM(F12:G12) -> 0.5 | I12: =A12&"|"&B12 -> Long (>7 yrs)|Conservative
A13: Long (>7 yrs) | B13: Moderate | C13: 0 | D13: 0.2 | E13: 0.1 | F13: 0.45 | G13: 0.25 | H13: =SUM(F13:G13) -> 0.7 | I13: =A13&"|"&B13 -> Long (>7 yrs)|Moderate
A14: Long (>7 yrs) | B14: Aggressive | C14: 0 | D14: 0.05 | E14: 0.05 | F14: 0.5 | G14: 0.4 | H14: =SUM(F14:G14) -> 0.9 | I14: =A14&"|"&B14 -> Long (>7 yrs)|Aggressive
A16: Override that beats the table above: if a goal is ≤1 year away (config.CAPITAL_PROTECTION_YEARS), it is forced to 100% Liquid Fund regardless of bucket or profile — money needed within a year is never put at market risk. [allocation.goal_allocation()]
A18: How the base portfolio changes for a specific user — mapping the brief's examples to what the code actually does
A19: Trigger (as listed in the brief) | B19: Actual rule in this application
A20: Shorter goal horizon → reduce equity | B20: Implemented directly: a goal's own "years" picks the row of the ALLOC table above (Short/Medium/Long); equity % rises with horizon in every profile.
A21: More dependents → increase defensive assets | B21: Implemented indirectly: dependents lower the risk-CAPACITY score (Sheet 5), which can pull the recommended profile down a tier (e.g. Aggressive → Moderate), which then selects a more defensive row of the ALLOC table. There is no separate, direct "dependents → allocation %" adjustment outside of this capacity-score path.
A22: Insufficient emergency fund → increase liquidity | B22: Implemented structurally rather than via the ALLOC percentages: any emergency-fund shortfall is carved out of the investable amount FIRST and kept 100% liquid, before the ALLOC table is even applied to the remaining money (Sheet 1, "Emergency-fund requirement"). Coverage also feeds the risk-capacity score.
A23: Stable income → potentially higher risk capacity | B23: Implemented: config.EMPLOYMENT_CAPACITY_PTS gives Salaried the highest capacity points (7) and Freelancer/Retired the lowest (4/3) - see Sheet 5.
A24: Large existing equity portfolio → reduce incremental equity allocation | B24: Implemented: allocation.tilt_for_existing() - see the worked formula below.
A25: Goal approaching → progressively de-risk | B25: Implemented only in the sense that re-running the tool as a goal's "years" counts down will move it into a safer bucket (and eventually the ≤1-year 100%-liquid override); there is no scheduled or automatic re-balancing that happens on its own between sessions.
A26: High-interest debt → recommend debt repayment before additional investment | B26: Advisory text only — does not change the allocation.
A28: Max/min allocation constraints: the ALLOC table itself is the hard constraint — each bucket x profile cell is a fixed set of percentages, not a continuously-optimised number, so there is no separate min/max cap beyond it except the ≤1-year 100%-liquid override above.
A30: Existing-portfolio tilt — allocation.tilt_for_existing()
A31: If the client's EXISTING holdings are already more (or less) equity-heavy than this goal's own target mix, new money is nudged the other way — proportionally, not all-or-nothing:
A32: diff = existing_equity_share − target_equity shift = OFFSET × diff × target_equity (clipped to ±target_equity) new equity weight = old weight × (1 − shift÷target_equity) the freed-up weight is absorbed into Debt first, then Liquid if Debt would go negative. OFFSET = 0.5 (config.EXISTING_PORTFOLIO_OFFSET): 0 would ignore existing holdings entirely, 1 would fully offset them.
A34: Quantity | B34: Value
A35: Target mix before tilt (Moderate / Long) | B35: Debt 20%, Gold 10%, Large-cap 45%, Mid-cap 25% → target_equity = 70%
A36: Client's existing holdings | B36: 90% equity (existing_equity_share = 0.90)
A37: diff = 0.90 − 0.70 | B37: 0.20
A38: shift = 0.5 × 0.20 × 0.70 | B38: 0.07 (7 percentage points of weight move out of equity)
A39: Large-cap: 0.45 − 0.07×(0.45÷0.70) | B39: 0.405 (40.5%)
A40: Mid-cap: 0.25 − 0.07×(0.25÷0.70) | B40: 0.225 (22.5%)
A41: Debt absorbs the shift: 0.20 + 0.07 | B41: 0.27 (27%) — Gold (10%) and Liquid (0%) unchanged
A42: Result | B42: 0% Liquid / 27% Debt / 10% Gold / 40.5% Large-cap / 22.5% Mid-cap — equity cut from 70% to 63%, because the client is already heavily in equity elsewhere
A44: This tilt is applied only to the blended OVERALL portfolio view, never to an individual goal's own protective allocation — so a near-term goal's capital-protection rule is never weakened by a client's unrelated existing holdings. Note: when every goal's funding happens to be ₹0 in a given period (see Sheet 7), the "existing" overall mix falls back to a simple average of each goal's own allocation (rather than a funding-weighted blend) — allocation.build_plan(), the agg.sum()==0 branch.

Sheet 7. Worked Example
A1: Worked Example — age-27 investor from the brief
A2: Run through this application's real engine on 2026-10-04 (verified against a live run of risk.py / allocation.py — see worked_example.py). Blue = input, black = live formula, green = linked from another sheet, pale-green = value also verified against the real app, pale-yellow = an input the brief did not specify, assumed here for illustration.
A4: Investor inputs
A5: Input | B5: Value | C5: Source
A6: Age | B6: 27 | C6: Given in the brief's Sheet-7 example
A7: Employment type | B7: Salaried | C7: ASSUMED — the brief did not specify this value; set here for illustration only (not stated in the brief)
A8: Annual income (₹) | B8: 1200000 | C8: Given in the brief's Sheet-7 example
A9: Monthly expenses (₹) | B9: 50000 | C9: Given in the brief's Sheet-7 example
A10: Dependents | B10: 1 | C10: Given in the brief's Sheet-7 example
A11: Monthly EMI (₹) | B11: 0 | C11: ASSUMED — the brief did not specify this value; set here for illustration only (not mentioned, treated as none)
A12: Stated risk appetite | B12: High | C12: Given in the brief's Sheet-7 example
A13: Scenario quiz Q1 (Sheet 5) | B13: 10 | C13: ASSUMED — the brief did not specify this value; set here for illustration only (quiz answers not given; set consistently with the stated "High" appetite)
A14: Scenario quiz Q2 (Sheet 5) | B14: 10 | C14: ASSUMED — the brief did not specify this value; set here for illustration only (same reason)
A15: Scenario quiz Q3 (Sheet 5) | B15: 10 | C15: ASSUMED — the brief did not specify this value; set here for illustration only (same reason)
A16: Existing emergency savings (₹) | B16: 200000 | C16: Given in the brief's Sheet-7 example
A17: Monthly SIP (₹) | B17: 25000 | C17: Given in the brief's Sheet-7 example
A18: SIP annual step-up | B18: 0 | C18: ASSUMED — the brief did not specify this value; set here for illustration only (not mentioned; app default)
A19: Retirement age | B19: 60 | C19: ASSUMED — the brief did not specify this value; set here for illustration only (standard app default; not restated in the brief's example)
A20: Goal 1 — Marriage: years to go | B20: 6 | C20: Given in the brief's Sheet-7 example
A21: Goal 1 — Marriage: cost today (₹) | B21: 1500000 | C21: ASSUMED — the brief did not specify this value; set here for illustration only (the brief names the goal but gives no ₹ figure; a realistic Indian urban-wedding cost is assumed for illustration)
A22: Existing equity / other holdings (₹) | B22: 0 / 0 | C22: ASSUMED — the brief did not specify this value; set here for illustration only (not mentioned, treated as none — so the existing-portfolio tilt on Sheet 6 does not apply here)
A24: Monthly income & emergency-fund requirement
A25: Monthly income (₹) | B25: =B8/12 -> 100000
A26: Disposable income = income − expenses − EMI | B26: =MAX(0,B25-B9-B11) -> 50000
A27: Savings rate = disposable ÷ income | B27: =B26/B25 -> 0.5
A28: Emergency-fund months = base(employment) + 1×dependents, capped 12 | B28: =MIN(12,IF(B7="Salaried",4,IF(B7="Self-employed / business owner",8,IF(B7="Freelancer / professional",8,IF(B7="Student",3,IF(B7="Retired",6,6)))))+B10) -> 5
A29: Emergency-fund target (₹) = months × expenses | B29: =B28*B9 -> 250000
A30: Emergency-fund shortfall (₹) = max(0, target − current) | B30: =MAX(0,B29-B16) -> 50000
A31: Emergency-fund coverage = min(1, current ÷ target) | B31: =MIN(1,B16/B29) -> 0.8
A33: Goals — inflation-adjusted future value
A34: Goal | B34: Years | C34: Today's value (₹) | D34: Inflation rate | E34: Inflated target (₹)
A35: Marriage | B35: =B20 -> 6 | C35: =B21 -> 1500000 | D35: ='2. Assumptions'!B13 -> 0.06 | E35: =C35*(1+D35)^B35 -> 2127778.7
A36: Retirement | B36: =B19-B6 -> 33 | C36: =B9*12*'2. Assumptions'!B39 -> 15000000 | D36: ='2. Assumptions'!B13 -> 0.06 | E36: =C36*(1+D36)^B36 -> 1.0260885e+08
A37: Retirement's "today value" is sized as 25× annual expenses (config.RETIREMENT_MULTIPLE, the "4% rule"), not a cost the user typed in directly.
A39: Risk appetite (willingness)
A40: Stated score (Low=3 / Moderate=6 / High=9) | B40: =IF(B12="High",9,IF(B12="Moderate",6,3)) -> 9
A41: Quiz mean | B41: =AVERAGE(B13,B14,B15) -> 10
A42: Willingness = 0.4×stated + 0.6×quiz mean | B42: =0.4*B40+0.6*B41 -> 9.6
A44: Risk capacity
A45: Age points | B45: =IF(B6<=30,9,IF(B6<=40,7,IF(B6<=50,5,IF(B6<=60,3,2)))) -> 9
...
